Workbook
Name 北美洲: '標籤資料'!$B$2:$B$300
Name 亞太地區: '標籤資料'!$G$2:$G$300
Name 名稱_所屬洲別: '名稱對照'!$B$2:$B$1002
Name 非洲: '標籤資料'!$D$2:$D$300
Name 亞西地區: '標籤資料'!$F$2:$F$300
Name 洲別: '標籤資料'!$A$2:$A$300
Name 中南美洲: '標籤資料'!$C$2:$C$300
Name 歐洲: '標籤資料'!$E$2:$E$300

Sheet Updated 8 Sep. 2026
A1: 洲別 Continent | B1: 國別 Country | C1: 學校名稱 Partner Institutions | D1: 學術交流合約 MOU | E1: 交換學生合約 Student Exchange | F1: 雙聯學位合約 Dual Degree | G1: 雙聯領域 Dual Degree Fields | H1: 其他合約 Other | I1: 註記 Remark
A2: 亞太地區 Asia Pacific | B2: 澳洲 Australia | C2: 墨爾本皇家理工學院 Royal Melbourne Institute of Technology | D2: V
A3: 亞太地區 Asia Pacific | B3: 澳洲 Australia | C3: 雪梨科技大學 University of Technology Sydney | D3: V | F3: PhD | G3: All | I3: NYCU
A4: 亞太地區 Asia Pacific | B4: 澳洲 Australia | C4: 新南威爾斯大學 University of New South Wales (UNSW) | D4: V
A5: 亞太地區 Asia Pacific | B5: 澳洲 Australia | C5: 昆士蘭科技大學 Queensland University of Technology (QUT) | D5: V
A6: 亞太地區 Asia Pacific | B6: 澳洲 Australia | C6: 雪梨大學 University of Sydney | D6: V
A7: 亞太地區 Asia Pacific | B7: 澳洲 Australia | C7: 西澳大學 The University of Western Australia (UWA) | D7: V | I7: NYCU
A8: 亞太地區 Asia Pacific | B8: 澳洲 Australia | C8: 墨爾本大學 The University of Melbourne | F8: MS | G8: 法 Law | I8: NYCU
A9: 亞太地區 Asia Pacific | B9: 澳洲 Australia | C9: 西雪梨大學 Western Sydney University | D9: V | I9: NYCU
A10: 亞太地區 Asia Pacific | B10: 紐西蘭 New Zealand | C10: 奧克蘭理工大學 Auckland University of Technology (AUT) | E10: V | I10: NYCU
A11: 亞太地區 Asia Pacific | B11: 玻里尼西亞 (大溪地) Polynesia (Tahitia) | C11: 法屬玻里尼西亞大學 University of French Polynesia | D11: V | E11: V
A12: 中南美洲 Central and South America | B12: 阿根廷 Argentina | C12: 國立南方大學 Universidad Nacional del Sur | E12: V
A13: 中南美洲 Central and South America | B13: 智利 Chile | C13: 智利天主教大學 Pontifical Catholic University of Chile | D13: V | E13: V | I13: NYCU
A14: 北美洲 North America | B14: 加拿大 Canada | C14: 蒙特婁理工大學 Polytechnique Montréal | D14: V | E14: V | I14: NYCU 原名: École Polytechnique de Montréal (EPM)
A15: 北美洲 North America | B15: 加拿大 Canada | C15: 滑鐵盧大學 University of Waterloo | D15: V | I15: NYCU
A16: 北美洲 North America | B16: 加拿大 Canada | C16: 魁北克大學蒙特婁分校 Université du Québec à Montréal | D16: V | E16: V
A17: 北美洲 North America | B17: 加拿大 Canada | C17: 高等工程技術學院 École de Technologie Supérieure (ETS) | D17: V | E17: V
A18: 北美洲 North America | B18: 加拿大 Canada | C18: 英屬哥倫比亞大學 The University of British Columbia (UBC) | D18: V (Summer Program) | I18: NYCU
A19: 北美洲 North America | B19: 加拿大 Canada | C19: 里賈納大學 University of Regina | D19: V | E19: V | I19: NYCU
A20: 北美洲 North America | B20: 加拿大 Canada | C20: 加拿大國家研究院 National Research Council of Canada | D20: V | I20: NYCU
A21: 北美洲 North America | B21: 加拿大 Canada | C21: 新布倫瑞克大學 University of New Brunswick | D21: V | E21: V | I21: NYCU
A22: 中南美洲 Central and South America | B22: 秘魯 Peru | C22: 阿拉斯秘鲁大學 Universidad Alas Peruanas | D22: V | E22: V
A23: 中南美洲 Central and South America | B23: 墨西哥 Mexico | C23: 大都會自治大學 Universidad Autónoma Metropolitana (UAM) | D23: V | E23: V | I23: NYCU
A24: 中南美洲 Central and South America | B24: 哥倫比亞 Colombia | C24: 哥倫比亞教育暨科技大學 Pedagogical and Technological University of Colombia (UPTC) | D24: V | I24: NYCU
A25: 北美洲 North America | B25: 美國 USA | C25: 羅徹斯特理工學院 Rochester Institute of Technology (RIT) | D25: V | F25: MBA | G25: 企業管理碩士學位學程 GMBA
A26: 北美洲 North America | B26: 美國 USA | C26: 北德州大學 University of North Texas (UNT) | D26: V | E26: V | I26: NYCU
A27: 北美洲 North America | B27: 美國 USA | C27: 杜蘭大學 Tulane University | D27: V
A28: 北美洲 North America | B28: 美國 USA | C28: 華盛頓大學 University of Washington | D28: V | I28: NYCU
A29: 北美洲 North America | B29: 美國 USA | C29: 明尼蘇達大學 University of Minnesota | D29: V | I29: NYCU
A30: 北美洲 North America | B30: 美國 USA | C30: 紐澤西理工學院 New Jersey Institute of Technology | D30: V | E30: V
A31: 北美洲 North America | B31: 美國 USA | C31: 杜克大學 Duke University | F31: LL.M | G31: 科技法律 Technology Law
A32: 北美洲 North America | B32: 美國 USA | C32: 卡內基美隆大學 Carnegie Mellon University | E32: V
A33: 北美洲 North America | B33: 美國 USA | C33: 北卡羅萊納州立大學 North Carolina State University | F33: MS、PhD | G33: 管理 Management | I33: NYCU
A34: 北美洲 North America | B34: 美國 USA | C34: 約翰馬歇爾法學院 The John Marshall Law School | F34: LL.M | G34: 科技法律 Technology Law
A35: 北美洲 North America | B35: 美國 USA | C35: 加州大學 洛杉磯分校 University of California, Los Angeles (UCLA) | D35: V | F35: MS & PhD | G35: 半導體 Semiconductor | I35: NYCU
A36: 北美洲 North America | B36: 美國 USA | C36: 伊利諾大學 香檳分校 Univeristy of Illinois at Urbana-Champaign (UIUC) | D36: V | E36: V | F36: (1) 3+2 program (2) 3+2.5 program | G36: (1) 材料科學與工程 Material Science and Engineering (2) 資訊 Computer Science | I36: NYCU
A37: 北美洲 North America | B37: 美國 USA | C37: 加州大學 聖地牙哥分校 University of California, San Diego (UCSD) | D37: V | F37: BS-MS 3+2 Program | G37: 土木工程 Civil Engineering | I37: NYCU-MOU
A38: 北美洲 North America | B38: 美國 USA | C38: 馬里蘭大學 巴爾的摩分校 University of Maryland, Baltimore | F38: PhD | G38: 電機工程 Electrical and Computer Engineering
A39: 北美洲 North America | B39: 美國 USA | C39: 凱斯西儲大學 Case Western Reserve University | D39: V | I39: NYCU
A40: 北美洲 North America | B40: 美國 USA | C40: 科羅拉多大學 波德分校 University of Colorado Boulder | E40: V | I40: NYCU
...

Sheet 標籤資料
A1: 洲別 | B1: 北美洲 North America | C1: 中南美洲 Central and South America | D1: 非洲 Africa | E1: 歐洲 Europe | F1: 亞西地區 West Asia | G1: 亞太地區 Asia Pacific
A2: 北美洲 North America | B2: {=IFERROR(OFFSET('名稱對照'!E$1,SMALL(IF(名稱_所屬洲別="NA",ROW(名稱_所屬洲別),""),row(1:1))-1,0),"")} -> 加拿大 Canada | C2: {=IFERROR(OFFSET('名稱對照'!E$1,SMALL(IF(名稱_所屬洲別="SA",ROW(名稱_所屬洲別),""),row(1:1))-1,0),"")} -> 阿根廷 Argentina | D2: {=IFERROR(OFFSET('名稱對照'!E$1,SMALL(IF(名稱_所屬洲別="AF",ROW(名稱_所屬洲別),""),row(1:1))-1,0),"")} -> 安哥拉 Angola | E2: {=IFERROR(OFFSET('名稱對照'!E$1,SMALL(IF(名稱_所屬洲別="EU",ROW(名稱_所屬洲別),""),row(1:1))-1,0),"")} -> 阿爾巴尼亞 Albania | F2: {=IFERROR(OFFSET('名稱對照'!E$1,SMALL(IF(名稱_所屬洲別="WA",ROW(名稱_所屬洲別),""),row(1:1))-1,0),"")} -> 阿富汗 Afghanistan | G2: {=IFERROR(OFFSET('名稱對照'!E$1,SMALL(IF(名稱_所屬洲別="AP",ROW(名稱_所屬洲別),""),row(1:1))-1,0),"")} -> 澳洲 Australia
A3: 中南美洲 Central and South America | B3: {=IFERROR(OFFSET('名稱對照'!E$1,SMALL(IF(名稱_所屬洲別="NA",ROW(名稱_所屬洲別),""),row(2:2))-1,0),"")} -> 美國 USA | C3: {=IFERROR(OFFSET('名稱對照'!E$1,SMALL(IF(名稱_所屬洲別="SA",ROW(名稱_所屬洲別),""),row(2:2))-1,0),"")} -> 巴哈馬 The Bahamas | D3: {=IFERROR(OFFSET('名稱對照'!E$1,SMALL(IF(名稱_所屬洲別="AF",ROW(名稱_所屬洲別),""),row(2:2))-1,0),"")} -> 蒲隆地 Burundi | E3: {=IFERROR(OFFSET('名稱對照'!E$1,SMALL(IF(名稱_所屬洲別="EU",ROW(名稱_所屬洲別),""),row(2:2))-1,0),"")} -> 奧地利 Austria | F3: {=IFERROR(OFFSET('名稱對照'!E$1,SMALL(IF(名稱_所屬洲別="WA",ROW(名稱_所屬洲別),""),row(2:2))-1,0),"")} -> 阿拉伯聯合大公國 United Arab Emirates | G3: {=IFERROR(OFFSET('名稱對照'!E$1,SMALL(IF(名稱_所屬洲別="AP",ROW(名稱_所屬洲別),""),row(2:2))-1,0),"")} -> 孟加拉 Bangladesh
A4: 非洲 Africa | B4: {=IFERROR(OFFSET('名稱對照'!E$1,SMALL(IF(名稱_所屬洲別="NA",ROW(名稱_所屬洲別),""),row(3:3))-1,0),"")} -> 格陵蘭 Greenland | C4: {=IFERROR(OFFSET('名稱對照'!E$1,SMALL(IF(名稱_所屬洲別="SA",ROW(名稱_所屬洲別),""),row(3:3))-1,0),"")} -> 貝里斯 Belize | D4: {=IFERROR(OFFSET('名稱對照'!E$1,SMALL(IF(名稱_所屬洲別="AF",ROW(名稱_所屬洲別),""),row(3:3))-1,0),"")} -> 貝南 Benin | E4: {=IFERROR(OFFSET('名稱對照'!E$1,SMALL(IF(名稱_所屬洲別="EU",ROW(名稱_所屬洲別),""),row(3:3))-1,0),"")} -> 比利時 Belgium | F4: {=IFERROR(OFFSET('名稱對照'!E$1,SMALL(IF(名稱_所屬洲別="WA",ROW(名稱_所屬洲別),""),row(3:3))-1,0),"")} -> 亞美尼亞 Armenia | G4: {=IFERROR(OFFSET('名稱對照'!E$1,SMALL(IF(名稱_所屬洲別="AP",ROW(名稱_所屬洲別),""),row(3:3))-1,0),"")} -> 汶萊 Brunei
A5: 歐洲 Europe | B5: {=IFERROR(OFFSET('名稱對照'!E$1,SMALL(IF(名稱_所屬洲別="NA",ROW(名稱_所屬洲別),""),row(4:4))-1,0),"")} | C5: {=IFERROR(OFFSET('名稱對照'!E$1,SMALL(IF(名稱_所屬洲別="SA",ROW(名稱_所屬洲別),""),row(4:4))-1,0),"")} -> 玻利維亞 Bolivia | D5: {=IFERROR(OFFSET('名稱對照'!E$1,SMALL(IF(名稱_所屬洲別="AF",ROW(名稱_所屬洲別),""),row(4:4))-1,0),"")} -> 布吉納法索 Burkina Faso | E5: {=IFERROR(OFFSET('名稱對照'!E$1,SMALL(IF(名稱_所屬洲別="EU",ROW(名稱_所屬洲別),""),row(4:4))-1,0),"")} -> 保加利亞 Bulgaria | F5: {=IFERROR(OFFSET('名稱對照'!E$1,SMALL(IF(名稱_所屬洲別="WA",ROW(名稱_所屬洲別),""),row(4:4))-1,0),"")} -> 亞塞拜然共和國 Azerbaijan | G5: {=IFERROR(OFFSET('名稱對照'!E$1,SMALL(IF(名稱_所屬洲別="AP",ROW(名稱_所屬洲別),""),row(4:4))-1,0),"")} -> 不丹 Bhutan
A6: 亞西地區 West Asia | B6: {=IFERROR(OFFSET('名稱對照'!E$1,SMALL(IF(名稱_所屬洲別="NA",ROW(名稱_所屬洲別),""),row(5:5))-1,0),"")} | C6: {=IFERROR(OFFSET('名稱對照'!E$1,SMALL(IF(名稱_所屬洲別="SA",ROW(名稱_所屬洲別),""),row(5:5))-1,0),"")} -> 巴西 Brazil | D6: {=IFERROR(OFFSET('名稱對照'!E$1,SMALL(IF(名稱_所屬洲別="AF",ROW(名稱_所屬洲別),""),row(5:5))-1,0),"")} -> 波札那 Botswana | E6: {=IFERROR(OFFSET('名稱對照'!E$1,SMALL(IF(名稱_所屬洲別="EU",ROW(名稱_所屬洲別),""),row(5:5))-1,0),"")} -> 波士尼亞與赫塞哥維納 Bosnia and Herzegovina | F6: {=IFERROR(OFFSET('名稱對照'!E$1,SMALL(IF(名稱_所屬洲別="WA",ROW(名稱_所屬洲別),""),row(5:5))-1,0),"")} -> 賽普勒斯 Cyprus | G6: {=IFERROR(OFFSET('名稱對照'!E$1,SMALL(IF(名稱_所屬洲別="AP",ROW(名稱_所屬洲別),""),row(5:5))-1,0),"")} -> 大陸地區 Mainland China
A7: 亞太地區 Asia Pacific | B7: {=IFERROR(OFFSET('名稱對照'!E$1,SMALL(IF(名稱_所屬洲別="NA",ROW(名稱_所屬洲別),""),row(6:6))-1,0),"")} | C7: {=IFERROR(OFFSET('名稱對照'!E$1,SMALL(IF(名稱_所屬洲別="SA",ROW(名稱_所屬洲別),""),row(6:6))-1,0),"")} -> 智利 Chile | D7: {=IFERROR(OFFSET('名稱對照'!E$1,SMALL(IF(名稱_所屬洲別="AF",ROW(名稱_所屬洲別),""),row(6:6))-1,0),"")} -> 中非共和國 Central African Republic | E7: {=IFERROR(OFFSET('名稱對照'!E$1,SMALL(IF(名稱_所屬洲別="EU",ROW(名稱_所屬洲別),""),row(6:6))-1,0),"")} -> 白俄羅斯 Belarus | F7: {=IFERROR(OFFSET('名稱對照'!E$1,SMALL(IF(名稱_所屬洲別="WA",ROW(名稱_所屬洲別),""),row(6:6))-1,0),"")} -> 喬治亞 Georgia | G7: {=IFERROR(OFFSET('名稱對照'!E$1,SMALL(IF(名稱_所屬洲別="AP",ROW(名稱_所屬洲別),""),row(6:6))-1,0),"")} -> 斐濟 Fiji
B8: {=IFERROR(OFFSET('名稱對照'!E$1,SMALL(IF(名稱_所屬洲別="NA",ROW(名稱_所屬洲別),""),row(7:7))-1,0),"")} | C8: {=IFERROR(OFFSET('名稱對照'!E$1,SMALL(IF(名稱_所屬洲別="SA",ROW(名稱_所屬洲別),""),row(7:7))-1,0),"")} -> 哥倫比亞 Colombia | D8: {=IFERROR(OFFSET('名稱對照'!E$1,SMALL(IF(名稱_所屬洲別="AF",ROW(名稱_所屬洲別),""),row(7:7))-1,0),"")} -> 象牙海岸 Ivory Coast | E8: {=IFERROR(OFFSET('名稱對照'!E$1,SMALL(IF(名稱_所屬洲別="EU",ROW(名稱_所屬洲別),""),row(7:7))-1,0),"")} -> 瑞士 Switzerland | F8: {=IFERROR(OFFSET('名稱對照'!E$1,SMALL(IF(名稱_所屬洲別="WA",ROW(名稱_所屬洲別),""),row(7:7))-1,0),"")} -> 伊朗 Iran | G8: {=IFERROR(OFFSET('名稱對照'!E$1,SMALL(IF(名稱_所屬洲別="AP",ROW(名稱_所屬洲別),""),row(7:7))-1,0),"")} -> 印尼 Indonesia
B9: {=IFERROR(OFFSET('名稱對照'!E$1,SMALL(IF(名稱_所屬洲別="NA",ROW(名稱_所屬洲別),""),row(8:8))-1,0),"")} | C9: {=IFERROR(OFFSET('名稱對照'!E$1,SMALL(IF(名稱_所屬洲別="SA",ROW(名稱_所屬洲別),""),row(8:8))-1,0),"")} -> 哥斯大黎加 Costa Rica | D9: {=IFERROR(OFFSET('名稱對照'!E$1,SMALL(IF(名稱_所屬洲別="AF",ROW(名稱_所屬洲別),""),row(8:8))-1,0),"")} -> 喀麥隆 Cameroon | E9: {=IFERROR(OFFSET('名稱對照'!E$1,SMALL(IF(名稱_所屬洲別="EU",ROW(名稱_所屬洲別),""),row(8:8))-1,0),"")} -> 捷克 Czech Republic | F9: {=IFERROR(OFFSET('名稱對照'!E$1,SMALL(IF(名稱_所屬洲別="WA",ROW(名稱_所屬洲別),""),row(8:8))-1,0),"")} -> 伊拉克 Iraq | G9: {=IFERROR(OFFSET('名稱對照'!E$1,SMALL(IF(名稱_所屬洲別="AP",ROW(名稱_所屬洲別),""),row(8:8))-1,0),"")} -> 印度 India
B10: {=IFERROR(OFFSET('名稱對照'!E$1,SMALL(IF(名稱_所屬洲別="NA",ROW(名稱_所屬洲別),""),row(9:9))-1,0),"")} | C10: {=IFERROR(OFFSET('名稱對照'!E$1,SMALL(IF(名稱_所屬洲別="SA",ROW(名稱_所屬洲別),""),row(9:9))-1,0),"")} -> 古巴 Cuba | D10: {=IFERROR(OFFSET('名稱對照'!E$1,SMALL(IF(名稱_所屬洲別="AF",ROW(名稱_所屬洲別),""),row(9:9))-1,0),"")} -> 剛果民主共和國 Democratic Republic of the Congo | E10: {=IFERROR(OFFSET('名稱對照'!E$1,SMALL(IF(名稱_所屬洲別="EU",ROW(名稱_所屬洲別),""),row(9:9))-1,0),"")} -> 德國 Germany | F10: {=IFERROR(OFFSET('名稱對照'!E$1,SMALL(IF(名稱_所屬洲別="WA",ROW(名稱_所屬洲別),""),row(9:9))-1,0),"")} -> 以色列 Israel | G10: {=IFERROR(OFFSET('名稱對照'!E$1,SMALL(IF(名稱_所屬洲別="AP",ROW(名稱_所屬洲別),""),row(9:9))-1,0),"")} -> 日本 Japan
B11: {=IFERROR(OFFSET('名稱對照'!E$1,SMALL(IF(名稱_所屬洲別="NA",ROW(名稱_所屬洲別),""),row(10:10))-1,0),"")} | C11: {=IFERROR(OFFSET('名稱對照'!E$1,SMALL(IF(名稱_所屬洲別="SA",ROW(名稱_所屬洲別),""),row(10:10))-1,0),"")} -> 多明尼加 Dominican Republic | D11: {=IFERROR(OFFSET('名稱對照'!E$1,SMALL(IF(名稱_所屬洲別="AF",ROW(名稱_所屬洲別),""),row(10:10))-1,0),"")} -> 剛果共和國 Republic of the Congo | E11: {=IFERROR(OFFSET('名稱對照'!E$1,SMALL(IF(名稱_所屬洲別="EU",ROW(名稱_所屬洲別),""),row(10:10))-1,0),"")} -> 丹麥 Denmark | F11: {=IFERROR(OFFSET('名稱對照'!E$1,SMALL(IF(名稱_所屬洲別="WA",ROW(名稱_所屬洲別),""),row(10:10))-1,0),"")} -> 約旦 Jordan | G11: {=IFERROR(OFFSET('名稱對照'!E$1,SMALL(IF(名稱_所屬洲別="AP",ROW(名稱_所屬洲別),""),row(10:10))-1,0),"")} -> 柬埔寨 Cambodia
B12: {=IFERROR(OFFSET('名稱對照'!E$1,SMALL(IF(名稱_所屬洲別="NA",ROW(名稱_所屬洲別),""),row(11:11))-1,0),"")} | C12: {=IFERROR(OFFSET('名稱對照'!E$1,SMALL(IF(名稱_所屬洲別="SA",ROW(名稱_所屬洲別),""),row(11:11))-1,0),"")} -> 厄瓜多 Ecuador | D12: {=IFERROR(OFFSET('名稱對照'!E$1,SMALL(IF(名稱_所屬洲別="AF",ROW(名稱_所屬洲別),""),row(11:11))-1,0),"")} -> 吉布地 Djibouti | E12: {=IFERROR(OFFSET('名稱對照'!E$1,SMALL(IF(名稱_所屬洲別="EU",ROW(名稱_所屬洲別),""),row(11:11))-1,0),"")} -> 西班牙 Spain | F12: {=IFERROR(OFFSET('名稱對照'!E$1,SMALL(IF(名稱_所屬洲別="WA",ROW(名稱_所屬洲別),""),row(11:11))-1,0),"")} -> 哈薩克 Kazakhstan | G12: {=IFERROR(OFFSET('名稱對照'!E$1,SMALL(IF(名稱_所屬洲別="AP",ROW(名稱_所屬洲別),""),row(11:11))-1,0),"")} -> 韓國 South Korea
B13: {=IFERROR(OFFSET('名稱對照'!E$1,SMALL(IF(名稱_所屬洲別="NA",ROW(名稱_所屬洲別),""),row(12:12))-1,0),"")} | C13: {=IFERROR(OFFSET('名稱對照'!E$1,SMALL(IF(名稱_所屬洲別="SA",ROW(名稱_所屬洲別),""),row(12:12))-1,0),"")} -> 福克蘭群島 Falkland Islands | D13: {=IFERROR(OFFSET('名稱對照'!E$1,SMALL(IF(名稱_所屬洲別="AF",ROW(名稱_所屬洲別),""),row(12:12))-1,0),"")} -> 阿爾及利亞 Algeria | E13: {=IFERROR(OFFSET('名稱對照'!E$1,SMALL(IF(名稱_所屬洲別="EU",ROW(名稱_所屬洲別),""),row(12:12))-1,0),"")} -> 愛沙尼亞 Estonia | F13: {=IFERROR(OFFSET('名稱對照'!E$1,SMALL(IF(名稱_所屬洲別="WA",ROW(名稱_所屬洲別),""),row(12:12))-1,0),"")} -> 吉爾吉斯 Kyrgyzstan | G13: {=IFERROR(OFFSET('名稱對照'!E$1,SMALL(IF(名稱_所屬洲別="AP",ROW(名稱_所屬洲別),""),row(12:12))-1,0),"")} -> 寮國 Laos
B14: {=IFERROR(OFFSET('名稱對照'!E$1,SMALL(IF(名稱_所屬洲別="NA",ROW(名稱_所屬洲別),""),row(13:13))-1,0),"")} | C14: {=IFERROR(OFFSET('名稱對照'!E$1,SMALL(IF(名稱_所屬洲別="SA",ROW(名稱_所屬洲別),""),row(13:13))-1,0),"")} -> 法屬圭亞那 French Guiana | D14: {=IFERROR(OFFSET('名稱對照'!E$1,SMALL(IF(名稱_所屬洲別="AF",ROW(名稱_所屬洲別),""),row(13:13))-1,0),"")} -> 埃及 Egypt | E14: {=IFERROR(OFFSET('名稱對照'!E$1,SMALL(IF(名稱_所屬洲別="EU",ROW(名稱_所屬洲別),""),row(13:13))-1,0),"")} -> 芬蘭 Finland | F14: {=IFERROR(OFFSET('名稱對照'!E$1,SMALL(IF(名稱_所屬洲別="WA",ROW(名稱_所屬洲別),""),row(13:13))-1,0),"")} -> 科威特 Kuwait | G14: {=IFERROR(OFFSET('名稱對照'!E$1,SMALL(IF(名稱_所屬洲別="AP",ROW(名稱_所屬洲別),""),row(13:13))-1,0),"")} -> 斯里蘭卡 Sri Lanka
B15: {=IFERROR(OFFSET('名稱對照'!E$1,SMALL(IF(名稱_所屬洲別="NA",ROW(名稱_所屬洲別),""),row(14:14))-1,0),"")} | C15: {=IFERROR(OFFSET('名稱對照'!E$1,SMALL(IF(名稱_所屬洲別="SA",ROW(名稱_所屬洲別),""),row(14:14))-1,0),"")} -> 瓜地馬拉 Guatemala | D15: {=IFERROR(OFFSET('名稱對照'!E$1,SMALL(IF(名稱_所屬洲別="AF",ROW(名稱_所屬洲別),""),row(14:14))-1,0),"")} -> 厄利垂亞 Eritrea | E15: {=IFERROR(OFFSET('名稱對照'!E$1,SMALL(IF(名稱_所屬洲別="EU",ROW(名稱_所屬洲別),""),row(14:14))-1,0),"")} -> 法國 France | F15: {=IFERROR(OFFSET('名稱對照'!E$1,SMALL(IF(名稱_所屬洲別="WA",ROW(名稱_所屬洲別),""),row(14:14))-1,0),"")} -> 黎巴嫩 Lebanon | G15: {=IFERROR(OFFSET('名稱對照'!E$1,SMALL(IF(名稱_所屬洲別="AP",ROW(名稱_所屬洲別),""),row(14:14))-1,0),"")} -> 緬甸 Myanmar
B16: {=IFERROR(OFFSET('名稱對照'!E$1,SMALL(IF(名稱_所屬洲別="NA",ROW(名稱_所屬洲別),""),row(15:15))-1,0),"")} | C16: {=IFERROR(OFFSET('名稱對照'!E$1,SMALL(IF(名稱_所屬洲別="SA",ROW(名稱_所屬洲別),""),row(15:15))-1,0),"")} -> 蓋亞那 Guyana | D16: {=IFERROR(OFFSET('名稱對照'!E$1,SMALL(IF(名稱_所屬洲別="AF",ROW(名稱_所屬洲別),""),row(15:15))-1,0),"")} -> 衣索比亞 Ethiopia | E16: {=IFERROR(OFFSET('名稱對照'!E$1,SMALL(IF(名稱_所屬洲別="EU",ROW(名稱_所屬洲別),""),row(15:15))-1,0),"")} -> 英國 United Kingdom | F16: {=IFERROR(OFFSET('名稱對照'!E$1,SMALL(IF(名稱_所屬洲別="WA",ROW(名稱_所屬洲別),""),row(15:15))-1,0),"")} -> 蒙古國 Mongolia | G16: {=IFERROR(OFFSET('名稱對照'!E$1,SMALL(IF(名稱_所屬洲別="AP",ROW(名稱_所屬洲別),""),row(15:15))-1,0),"")} -> 馬來西亞 Malaysia
B17: {=IFERROR(OFFSET('名稱對照'!E$1,SMALL(IF(名稱_所屬洲別="NA",ROW(名稱_所屬洲別),""),row(16:16))-1,0),"")} | C17: {=IFERROR(OFFSET('名稱對照'!E$1,SMALL(IF(名稱_所屬洲別="SA",ROW(名稱_所屬洲別),""),row(16:16))-1,0),"")} -> 宏都拉斯 Honduras | D17: {=IFERROR(OFFSET('名稱對照'!E$1,SMALL(IF(名稱_所屬洲別="AF",ROW(名稱_所屬洲別),""),row(16:16))-1,0),"")} -> 加彭 Gabon | E17: {=IFERROR(OFFSET('名稱對照'!E$1,SMALL(IF(名稱_所屬洲別="EU",ROW(名稱_所屬洲別),""),row(16:16))-1,0),"")} -> 希臘 Greece | F17: {=IFERROR(OFFSET('名稱對照'!E$1,SMALL(IF(名稱_所屬洲別="WA",ROW(名稱_所屬洲別),""),row(16:16))-1,0),"")} -> 阿曼 Oman | G17: {=IFERROR(OFFSET('名稱對照'!E$1,SMALL(IF(名稱_所屬洲別="AP",ROW(名稱_所屬洲別),""),row(16:16))-1,0),"")} -> 新喀里多尼亞 New Caledonia
B18: {=IFERROR(OFFSET('名稱對照'!E$1,SMALL(IF(名稱_所屬洲別="NA",ROW(名稱_所屬洲別),""),row(17:17))-1,0),"")} | C18: {=IFERROR(OFFSET('名稱對照'!E$1,SMALL(IF(名稱_所屬洲別="SA",ROW(名稱_所屬洲別),""),row(17:17))-1,0),"")} -> 海地 Haiti | D18: {=IFERROR(OFFSET('名稱對照'!E$1,SMALL(IF(名稱_所屬洲別="AF",ROW(名稱_所屬洲別),""),row(17:17))-1,0),"")} -> 迦納 Ghana | E18: {=IFERROR(OFFSET('名稱對照'!E$1,SMALL(IF(名稱_所屬洲別="EU",ROW(名稱_所屬洲別),""),row(17:17))-1,0),"")} -> 克羅埃西亞 Croatia | F18: {=IFERROR(OFFSET('名稱對照'!E$1,SMALL(IF(名稱_所屬洲別="WA",ROW(名稱_所屬洲別),""),row(17:17))-1,0),"")} -> 巴基斯坦 Pakistan | G18: {=IFERROR(OFFSET('名稱對照'!E$1,SMALL(IF(名稱_所屬洲別="AP",ROW(名稱_所屬洲別),""),row(17:17))-1,0),"")} -> 尼泊爾 Nepal
B19: {=IFERROR(OFFSET('名稱對照'!E$1,SMALL(IF(名稱_所屬洲別="NA",ROW(名稱_所屬洲別),""),row(18:18))-1,0),"")} | C19: {=IFERROR(OFFSET('名稱對照'!E$1,SMALL(IF(名稱_所屬洲別="SA",ROW(名稱_所屬洲別),""),row(18:18))-1,0),"")} -> 牙買加 Jamaica | D19: {=IFERROR(OFFSET('名稱對照'!E$1,SMALL(IF(名稱_所屬洲別="AF",ROW(名稱_所屬洲別),""),row(18:18))-1,0),"")} -> 幾內亞 Guinea | E19: {=IFERROR(OFFSET('名稱對照'!E$1,SMALL(IF(名稱_所屬洲別="EU",ROW(名稱_所屬洲別),""),row(18:18))-1,0),"")} -> 匈牙利 Hungary | F19: {=IFERROR(OFFSET('名稱對照'!E$1,SMALL(IF(名稱_所屬洲別="WA",ROW(名稱_所屬洲別),""),row(18:18))-1,0),"")} -> 卡達 Qatar | G19: {=IFERROR(OFFSET('名稱對照'!E$1,SMALL(IF(名稱_所屬洲別="AP",ROW(名稱_所屬洲別),""),row(18:18))-1,0),"")} -> 紐西蘭 New Zealand
B20: {=IFERROR(OFFSET('名稱對照'!E$1,SMALL(IF(名稱_所屬洲別="NA",ROW(名稱_所屬洲別),""),row(19:19))-1,0),"")} | C20: {=IFERROR(OFFSET('名稱對照'!E$1,SMALL(IF(名稱_所屬洲別="SA",ROW(名稱_所屬洲別),""),row(19:19))-1,0),"")} -> 墨西哥 Mexico | D20: {=IFERROR(OFFSET('名稱對照'!E$1,SMALL(IF(名稱_所屬洲別="AF",ROW(名稱_所屬洲別),""),row(19:19))-1,0),"")} -> 甘比亞 Gambia | E20: {=IFERROR(OFFSET('名稱對照'!E$1,SMALL(IF(名稱_所屬洲別="EU",ROW(名稱_所屬洲別),""),row(19:19))-1,0),"")} -> 愛爾蘭島 Ireland | F20: {=IFERROR(OFFSET('名稱對照'!E$1,SMALL(IF(名稱_所屬洲別="WA",ROW(名稱_所屬洲別),""),row(19:19))-1,0),"")} -> 俄羅斯 Russia | G20: {=IFERROR(OFFSET('名稱對照'!E$1,SMALL(IF(名稱_所屬洲別="AP",ROW(名稱_所屬洲別),""),row(19:19))-1,0),"")} -> 菲律賓 Philippines
B21: {=IFERROR(OFFSET('名稱對照'!E$1,SMALL(IF(名稱_所屬洲別="NA",ROW(名稱_所屬洲別),""),row(20:20))-1,0),"")} | C21: {=IFERROR(OFFSET('名稱對照'!E$1,SMALL(IF(名稱_所屬洲別="SA",ROW(名稱_所屬洲別),""),row(20:20))-1,0),"")} -> 尼加拉瓜 Nicaragua | D21: {=IFERROR(OFFSET('名稱對照'!E$1,SMALL(IF(名稱_所屬洲別="AF",ROW(名稱_所屬洲別),""),row(20:20))-1,0),"")} -> 幾內亞比索 Guinea Bissau | E21: {=IFERROR(OFFSET('名稱對照'!E$1,SMALL(IF(名稱_所屬洲別="EU",ROW(名稱_所屬洲別),""),row(20:20))-1,0),"")} -> 冰島 Iceland | F21: {=IFERROR(OFFSET('名稱對照'!E$1,SMALL(IF(名稱_所屬洲別="WA",ROW(名稱_所屬洲別),""),row(20:20))-1,0),"")} -> 沙烏地阿拉伯 Saudi Arabia | G21: {=IFERROR(OFFSET('名稱對照'!E$1,SMALL(IF(名稱_所屬洲別="AP",ROW(名稱_所屬洲別),""),row(20:20))-1,0),"")} -> 巴布亞紐幾內亞 Papua New Guinea
B22: {=IFERROR(OFFSET('名稱對照'!E$1,SMALL(IF(名稱_所屬洲別="NA",ROW(名稱_所屬洲別),""),row(21:21))-1,0),"")} | C22: {=IFERROR(OFFSET('名稱對照'!E$1,SMALL(IF(名稱_所屬洲別="SA",ROW(名稱_所屬洲別),""),row(21:21))-1,0),"")} -> 巴拿馬 Panama | D22: {=IFERROR(OFFSET('名稱對照'!E$1,SMALL(IF(名稱_所屬洲別="AF",ROW(名稱_所屬洲別),""),row(21:21))-1,0),"")} -> 赤道幾內亞 Equatorial Guinea | E22: {=IFERROR(OFFSET('名稱對照'!E$1,SMALL(IF(名稱_所屬洲別="EU",ROW(名稱_所屬洲別),""),row(21:21))-1,0),"")} -> 義大利 Italy | F22: {=IFERROR(OFFSET('名稱對照'!E$1,SMALL(IF(名稱_所屬洲別="WA",ROW(名稱_所屬洲別),""),row(21:21))-1,0),"")} -> 敘利亞 Syria | G22: {=IFERROR(OFFSET('名稱對照'!E$1,SMALL(IF(名稱_所屬洲別="AP",ROW(名稱_所屬洲別),""),row(21:21))-1,0),"")} -> 朝鮮民主主義人民共和國 North Korea
B23: {=IFERROR(OFFSET('名稱對照'!E$1,SMALL(IF(名稱_所屬洲別="NA",ROW(名稱_所屬洲別),""),row(22:22))-1,0),"")} | C23: {=IFERROR(OFFSET('名稱對照'!E$1,SMALL(IF(名稱_所屬洲別="SA",ROW(名稱_所屬洲別),""),row(22:22))-1,0),"")} -> 秘魯 Peru | D23: {=IFERROR(OFFSET('名稱對照'!E$1,SMALL(IF(名稱_所屬洲別="AF",ROW(名稱_所屬洲別),""),row(22:22))-1,0),"")} -> 肯亞 Kenya | E23: {=IFERROR(OFFSET('名稱對照'!E$1,SMALL(IF(名稱_所屬洲別="EU",ROW(名稱_所屬洲別),""),row(22:22))-1,0),"")} -> 立陶宛 Lithuania | F23: {=IFERROR(OFFSET('名稱對照'!E$1,SMALL(IF(名稱_所屬洲別="WA",ROW(名稱_所屬洲別),""),row(22:22))-1,0),"")} -> 塔吉克 Tajikistan | G23: {=IFERROR(OFFSET('名稱對照'!E$1,SMALL(IF(名稱_所屬洲別="AP",ROW(名稱_所屬洲別),""),row(22:22))-1,0),"")} -> 索羅門群島 Solomon Islands
B24: {=IFERROR(OFFSET('名稱對照'!E$1,SMALL(IF(名稱_所屬洲別="NA",ROW(名稱_所屬洲別),""),row(23:23))-1,0),"")} | C24: {=IFERROR(OFFSET('名稱對照'!E$1,SMALL(IF(名稱_所屬洲別="SA",ROW(名稱_所屬洲別),""),row(23:23))-1,0),"")} -> 波多黎各 Puerto Rico | D24: {=IFERROR(OFFSET('名稱對照'!E$1,SMALL(IF(名稱_所屬洲別="AF",ROW(名稱_所屬洲別),""),row(23:23))-1,0),"")} -> 賴比瑞亞 Liberia | E24: {=IFERROR(OFFSET('名稱對照'!E$1,SMALL(IF(名稱_所屬洲別="EU",ROW(名稱_所屬洲別),""),row(23:23))-1,0),"")} -> 盧森堡 Luxembourg | F24: {=IFERROR(OFFSET('名稱對照'!E$1,SMALL(IF(名稱_所屬洲別="WA",ROW(名稱_所屬洲別),""),row(23:23))-1,0),"")} -> 土庫曼 Turkmenistan | G24: {=IFERROR(OFFSET('名稱對照'!E$1,SMALL(IF(名稱_所屬洲別="AP",ROW(名稱_所屬洲別),""),row(23:23))-1,0),"")} -> 泰國 Thailand
B25: {=IFERROR(OFFSET('名稱對照'!E$1,SMALL(IF(名稱_所屬洲別="NA",ROW(名稱_所屬洲別),""),row(24:24))-1,0),"")} | C25: {=IFERROR(OFFSET('名稱對照'!E$1,SMALL(IF(名稱_所屬洲別="SA",ROW(名稱_所屬洲別),""),row(24:24))-1,0),"")} -> 巴拉圭 Paraguay | D25: {=IFERROR(OFFSET('名稱對照'!E$1,SMALL(IF(名稱_所屬洲別="AF",ROW(名稱_所屬洲別),""),row(24:24))-1,0),"")} -> 利比亞 Libya | E25: {=IFERROR(OFFSET('名稱對照'!E$1,SMALL(IF(名稱_所屬洲別="EU",ROW(名稱_所屬洲別),""),row(24:24))-1,0),"")} -> 拉脫維亞 Latvia | F25: {=IFERROR(OFFSET('名稱對照'!E$1,SMALL(IF(名稱_所屬洲別="WA",ROW(名稱_所屬洲別),""),row(24:24))-1,0),"")} -> 土耳其 Turkey | G25: {=IFERROR(OFFSET('名稱對照'!E$1,SMALL(IF(名稱_所屬洲別="AP",ROW(名稱_所屬洲別),""),row(24:24))-1,0),"")} -> 東帝汶 East Timor
B26: {=IFERROR(OFFSET('名稱對照'!E$1,SMALL(IF(名稱_所屬洲別="NA",ROW(名稱_所屬洲別),""),row(25:25))-1,0),"")} | C26: {=IFERROR(OFFSET('名稱對照'!E$1,SMALL(IF(名稱_所屬洲別="SA",ROW(名稱_所屬洲別),""),row(25:25))-1,0),"")} -> 薩爾瓦多 El Salvador | D26: {=IFERROR(OFFSET('名稱對照'!E$1,SMALL(IF(名稱_所屬洲別="AF",ROW(名稱_所屬洲別),""),row(25:25))-1,0),"")} -> 賴索托 Lesotho | E26: {=IFERROR(OFFSET('名稱對照'!E$1,SMALL(IF(名稱_所屬洲別="EU",ROW(名稱_所屬洲別),""),row(25:25))-1,0),"")} -> 摩爾多瓦 Moldova | F26: {=IFERROR(OFFSET('名稱對照'!E$1,SMALL(IF(名稱_所屬洲別="WA",ROW(名稱_所屬洲別),""),row(25:25))-1,0),"")} -> 烏克蘭 Ukraine | G26: {=IFERROR(OFFSET('名稱對照'!E$1,SMALL(IF(名稱_所屬洲別="AP",ROW(名稱_所屬洲別),""),row(25:25))-1,0),"")} -> 中華民國 Taiwan
B27: {=IFERROR(OFFSET('名稱對照'!E$1,SMALL(IF(名稱_所屬洲別="NA",ROW(名稱_所屬洲別),""),row(26:26))-1,0),"")} | C27: {=IFERROR(OFFSET('名稱對照'!E$1,SMALL(IF(名稱_所屬洲別="SA",ROW(名稱_所屬洲別),""),row(26:26))-1,0),"")} -> 蘇利南 Suriname | D27: {=IFERROR(OFFSET('名稱對照'!E$1,SMALL(IF(名稱_所屬洲別="AF",ROW(名稱_所屬洲別),""),row(26:26))-1,0),"")} -> 摩洛哥 Morocco | E27: {=IFERROR(OFFSET('名稱對照'!E$1,SMALL(IF(名稱_所屬洲別="EU",ROW(名稱_所屬洲別),""),row(26:26))-1,0),"")} -> 馬其頓共和國 Macedonia | F27: {=IFERROR(OFFSET('名稱對照'!E$1,SMALL(IF(名稱_所屬洲別="WA",ROW(名稱_所屬洲別),""),row(26:26))-1,0),"")} -> 烏茲別克 Uzbekistan | G27: {=IFERROR(OFFSET('名稱對照'!E$1,SMALL(IF(名稱_所屬洲別="AP",ROW(名稱_所屬洲別),""),row(26:26))-1,0),"")} -> 越南 Vietnam
B28: {=IFERROR(OFFSET('名稱對照'!E$1,SMALL(IF(名稱_所屬洲別="NA",ROW(名稱_所屬洲別),""),row(27:27))-1,0),"")} | C28: {=IFERROR(OFFSET('名稱對照'!E$1,SMALL(IF(名稱_所屬洲別="SA",ROW(名稱_所屬洲別),""),row(27:27))-1,0),"")} -> 千里達及托巴哥 Trinidad and Tobago | D28: {=IFERROR(OFFSET('名稱對照'!E$1,SMALL(IF(名稱_所屬洲別="AF",ROW(名稱_所屬洲別),""),row(27:27))-1,0),"")} -> 馬達加斯加 Madagascar | E28: {=IFERROR(OFFSET('名稱對照'!E$1,SMALL(IF(名稱_所屬洲別="EU",ROW(名稱_所屬洲別),""),row(27:27))-1,0),"")} -> 蒙特內哥羅 Montenegro | F28: {=IFERROR(OFFSET('名稱對照'!E$1,SMALL(IF(名稱_所屬洲別="WA",ROW(名稱_所屬洲別),""),row(27:27))-1,0),"")} -> 約旦河西岸地區 West Bank | G28: {=IFERROR(OFFSET('名稱對照'!E$1,SMALL(IF(名稱_所屬洲別="AP",ROW(名稱_所屬洲別),""),row(27:27))-1,0),"")} -> 萬那杜 Vanuatu
B29: {=IFERROR(OFFSET('名稱對照'!E$1,SMALL(IF(名稱_所屬洲別="NA",ROW(名稱_所屬洲別),""),row(28:28))-1,0),"")} | C29: {=IFERROR(OFFSET('名稱對照'!E$1,SMALL(IF(名稱_所屬洲別="SA",ROW(名稱_所屬洲別),""),row(28:28))-1,0),"")} -> 烏拉圭 Uruguay | D29: {=IFERROR(OFFSET('名稱對照'!E$1,SMALL(IF(名稱_所屬洲別="AF",ROW(名稱_所屬洲別),""),row(28:28))-1,0),"")} -> 馬利 Mali | E29: {=IFERROR(OFFSET('名稱對照'!E$1,SMALL(IF(名稱_所屬洲別="EU",ROW(名稱_所屬洲別),""),row(28:28))-1,0),"")} -> 荷蘭 Netherlands | F29: {=IFERROR(OFFSET('名稱對照'!E$1,SMALL(IF(名稱_所屬洲別="WA",ROW(名稱_所屬洲別),""),row(28:28))-1,0),"")} -> 葉門 Yemen | G29: {=IFERROR(OFFSET('名稱對照'!E$1,SMALL(IF(名稱_所屬洲別="AP",ROW(名稱_所屬洲別),""),row(28:28))-1,0),"")} -> 新加坡 Republic of Singapore
B30: {=IFERROR(OFFSET('名稱對照'!E$1,SMALL(IF(名稱_所屬洲別="NA",ROW(名稱_所屬洲別),""),row(29:29))-1,0),"")} | C30: {=IFERROR(OFFSET('名稱對照'!E$1,SMALL(IF(名稱_所屬洲別="SA",ROW(名稱_所屬洲別),""),row(29:29))-1,0),"")} -> 委內瑞拉 Venezuela | D30: {=IFERROR(OFFSET('名稱對照'!E$1,SMALL(IF(名稱_所屬洲別="AF",ROW(名稱_所屬洲別),""),row(29:29))-1,0),"")} -> 莫三比克 Mozambique | E30: {=IFERROR(OFFSET('名稱對照'!E$1,SMALL(IF(名稱_所屬洲別="EU",ROW(名稱_所屬洲別),""),row(29:29))-1,0),"")} -> 挪威 Norway | F30: {=IFERROR(OFFSET('名稱對照'!E$1,SMALL(IF(名稱_所屬洲別="WA",ROW(名稱_所屬洲別),""),row(29:29))-1,0),"")} | G30: {=IFERROR(OFFSET('名稱對照'!E$1,SMALL(IF(名稱_所屬洲別="AP",ROW(名稱_所屬洲別),""),row(29:29))-1,0),"")} -> 香港 Hong Kong
B31: {=IFERROR(OFFSET('名稱對照'!E$1,SMALL(IF(名稱_所屬洲別="NA",ROW(名稱_所屬洲別),""),row(30:30))-1,0),"")} | C31: {=IFERROR(OFFSET('名稱對照'!E$1,SMALL(IF(名稱_所屬洲別="SA",ROW(名稱_所屬洲別),""),row(30:30))-1,0),"")} | D31: {=IFERROR(OFFSET('名稱對照'!E$1,SMALL(IF(名稱_所屬洲別="AF",ROW(名稱_所屬洲別),""),row(30:30))-1,0),"")} -> 茅利塔尼亞 Mauritania | E31: {=IFERROR(OFFSET('名稱對照'!E$1,SMALL(IF(名稱_所屬洲別="EU",ROW(名稱_所屬洲別),""),row(30:30))-1,0),"")} -> 波蘭 Poland | F31: {=IFERROR(OFFSET('名稱對照'!E$1,SMALL(IF(名稱_所屬洲別="WA",ROW(名稱_所屬洲別),""),row(30:30))-1,0),"")} | G31: {=IFERROR(OFFSET('名稱對照'!E$1,SMALL(IF(名稱_所屬洲別="AP",ROW(名稱_所屬洲別),""),row(30:30))-1,0),"")} -> 澳門 Machu
B32: {=IFERROR(OFFSET('名稱對照'!E$1,SMALL(IF(名稱_所屬洲別="NA",ROW(名稱_所屬洲別),""),row(31:31))-1,0),"")} | C32: {=IFERROR(OFFSET('名稱對照'!E$1,SMALL(IF(名稱_所屬洲別="SA",ROW(名稱_所屬洲別),""),row(31:31))-1,0),"")} | D32: {=IFERROR(OFFSET('名稱對照'!E$1,SMALL(IF(名稱_所屬洲別="AF",ROW(名稱_所屬洲別),""),row(31:31))-1,0),"")} -> 馬拉威 Malawi | E32: {=IFERROR(OFFSET('名稱對照'!E$1,SMALL(IF(名稱_所屬洲別="EU",ROW(名稱_所屬洲別),""),row(31:31))-1,0),"")} -> 葡萄牙 Portugal | F32: {=IFERROR(OFFSET('名稱對照'!E$1,SMALL(IF(名稱_所屬洲別="WA",ROW(名稱_所屬洲別),""),row(31:31))-1,0),"")} | G32: {=IFERROR(OFFSET('名稱對照'!E$1,SMALL(IF(名稱_所屬洲別="AP",ROW(名稱_所屬洲別),""),row(31:31))-1,0),"")} -> 玻里尼西亞 (大溪地) Polynesia (Tahitia)
B33: {=IFERROR(OFFSET('名稱對照'!E$1,SMALL(IF(名稱_所屬洲別="NA",ROW(名稱_所屬洲別),""),row(32:32))-1,0),"")} | C33: {=IFERROR(OFFSET('名稱對照'!E$1,SMALL(IF(名稱_所屬洲別="SA",ROW(名稱_所屬洲別),""),row(32:32))-1,0),"")} | D33: {=IFERROR(OFFSET('名稱對照'!E$1,SMALL(IF(名稱_所屬洲別="AF",ROW(名稱_所屬洲別),""),row(32:32))-1,0),"")} -> 納米比亞 Namibia | E33: {=IFERROR(OFFSET('名稱對照'!E$1,SMALL(IF(名稱_所屬洲別="EU",ROW(名稱_所屬洲別),""),row(32:32))-1,0),"")} -> 羅馬尼亞 Romania | F33: {=IFERROR(OFFSET('名稱對照'!E$1,SMALL(IF(名稱_所屬洲別="WA",ROW(名稱_所屬洲別),""),row(32:32))-1,0),"")} | G33: {=IFERROR(OFFSET('名稱對照'!E$1,SMALL(IF(名稱_所屬洲別="AP",ROW(名稱_所屬洲別),""),row(32:32))-1,0),"")}
B34: {=IFERROR(OFFSET('名稱對照'!E$1,SMALL(IF(名稱_所屬洲別="NA",ROW(名稱_所屬洲別),""),row(33:33))-1,0),"")} | C34: {=IFERROR(OFFSET('名稱對照'!E$1,SMALL(IF(名稱_所屬洲別="SA",ROW(名稱_所屬洲別),""),row(33:33))-1,0),"")} | D34: {=IFERROR(OFFSET('名稱對照'!E$1,SMALL(IF(名稱_所屬洲別="AF",ROW(名稱_所屬洲別),""),row(33:33))-1,0),"")} -> 尼日 Niger | E34: {=IFERROR(OFFSET('名稱對照'!E$1,SMALL(IF(名稱_所屬洲別="EU",ROW(名稱_所屬洲別),""),row(33:33))-1,0),"")} -> 塞爾維亞 Republic of Serbia | F34: {=IFERROR(OFFSET('名稱對照'!E$1,SMALL(IF(名稱_所屬洲別="WA",ROW(名稱_所屬洲別),""),row(33:33))-1,0),"")} | G34: {=IFERROR(OFFSET('名稱對照'!E$1,SMALL(IF(名稱_所屬洲別="AP",ROW(名稱_所屬洲別),""),row(33:33))-1,0),"")}
B35: {=IFERROR(OFFSET('名稱對照'!E$1,SMALL(IF(名稱_所屬洲別="NA",ROW(名稱_所屬洲別),""),row(34:34))-1,0),"")} | C35: {=IFERROR(OFFSET('名稱對照'!E$1,SMALL(IF(名稱_所屬洲別="SA",ROW(名稱_所屬洲別),""),row(34:34))-1,0),"")} | D35: {=IFERROR(OFFSET('名稱對照'!E$1,SMALL(IF(名稱_所屬洲別="AF",ROW(名稱_所屬洲別),""),row(34:34))-1,0),"")} -> 奈及利亞 Nigeria | E35: {=IFERROR(OFFSET('名稱對照'!E$1,SMALL(IF(名稱_所屬洲別="EU",ROW(名稱_所屬洲別),""),row(34:34))-1,0),"")} -> 斯洛伐克 Slovakia | F35: {=IFERROR(OFFSET('名稱對照'!E$1,SMALL(IF(名稱_所屬洲別="WA",ROW(名稱_所屬洲別),""),row(34:34))-1,0),"")} | G35: {=IFERROR(OFFSET('名稱對照'!E$1,SMALL(IF(名稱_所屬洲別="AP",ROW(名稱_所屬洲別),""),row(34:34))-1,0),"")}
B36: {=IFERROR(OFFSET('名稱對照'!E$1,SMALL(IF(名稱_所屬洲別="NA",ROW(名稱_所屬洲別),""),row(35:35))-1,0),"")} | C36: {=IFERROR(OFFSET('名稱對照'!E$1,SMALL(IF(名稱_所屬洲別="SA",ROW(名稱_所屬洲別),""),row(35:35))-1,0),"")} | D36: {=IFERROR(OFFSET('名稱對照'!E$1,SMALL(IF(名稱_所屬洲別="AF",ROW(名稱_所屬洲別),""),row(35:35))-1,0),"")} -> 盧安達 Rwanda | E36: {=IFERROR(OFFSET('名稱對照'!E$1,SMALL(IF(名稱_所屬洲別="EU",ROW(名稱_所屬洲別),""),row(35:35))-1,0),"")} -> 斯洛維尼亞 Slovenia | F36: {=IFERROR(OFFSET('名稱對照'!E$1,SMALL(IF(名稱_所屬洲別="WA",ROW(名稱_所屬洲別),""),row(35:35))-1,0),"")} | G36: {=IFERROR(OFFSET('名稱對照'!E$1,SMALL(IF(名稱_所屬洲別="AP",ROW(名稱_所屬洲別),""),row(35:35))-1,0),"")}
B37: {=IFERROR(OFFSET('名稱對照'!E$1,SMALL(IF(名稱_所屬洲別="NA",ROW(名稱_所屬洲別),""),row(36:36))-1,0),"")} | C37: {=IFERROR(OFFSET('名稱對照'!E$1,SMALL(IF(名稱_所屬洲別="SA",ROW(名稱_所屬洲別),""),row(36:36))-1,0),"")} | D37: {=IFERROR(OFFSET('名稱對照'!E$1,SMALL(IF(名稱_所屬洲別="AF",ROW(名稱_所屬洲別),""),row(36:36))-1,0),"")} -> 西撒哈拉 Western Sahara | E37: {=IFERROR(OFFSET('名稱對照'!E$1,SMALL(IF(名稱_所屬洲別="EU",ROW(名稱_所屬洲別),""),row(36:36))-1,0),"")} -> 瑞典 Sweden | F37: {=IFERROR(OFFSET('名稱對照'!E$1,SMALL(IF(名稱_所屬洲別="WA",ROW(名稱_所屬洲別),""),row(36:36))-1,0),"")} | G37: {=IFERROR(OFFSET('名稱對照'!E$1,SMALL(IF(名稱_所屬洲別="AP",ROW(名稱_所屬洲別),""),row(36:36))-1,0),"")}
B38: {=IFERROR(OFFSET('名稱對照'!E$1,SMALL(IF(名稱_所屬洲別="NA",ROW(名稱_所屬洲別),""),row(37:37))-1,0),"")} | C38: {=IFERROR(OFFSET('名稱對照'!E$1,SMALL(IF(名稱_所屬洲別="SA",ROW(名稱_所屬洲別),""),row(37:37))-1,0),"")} | D38: {=IFERROR(OFFSET('名稱對照'!E$1,SMALL(IF(名稱_所屬洲別="AF",ROW(名稱_所屬洲別),""),row(37:37))-1,0),"")} -> 蘇丹共和國 Sudan | E38: {=IFERROR(OFFSET('名稱對照'!E$1,SMALL(IF(名稱_所屬洲別="EU",ROW(名稱_所屬洲別),""),row(37:37))-1,0),"")} | F38: {=IFERROR(OFFSET('名稱對照'!E$1,SMALL(IF(名稱_所屬洲別="WA",ROW(名稱_所屬洲別),""),row(37:37))-1,0),"")} | G38: {=IFERROR(OFFSET('名稱對照'!E$1,SMALL(IF(名稱_所屬洲別="AP",ROW(名稱_所屬洲別),""),row(37:37))-1,0),"")}
B39: {=IFERROR(OFFSET('名稱對照'!E$1,SMALL(IF(名稱_所屬洲別="NA",ROW(名稱_所屬洲別),""),row(38:38))-1,0),"")} | C39: {=IFERROR(OFFSET('名稱對照'!E$1,SMALL(IF(名稱_所屬洲別="SA",ROW(名稱_所屬洲別),""),row(38:38))-1,0),"")} | D39: {=IFERROR(OFFSET('名稱對照'!E$1,SMALL(IF(名稱_所屬洲別="AF",ROW(名稱_所屬洲別),""),row(38:38))-1,0),"")} -> 南蘇丹 South Sudan | E39: {=IFERROR(OFFSET('名稱對照'!E$1,SMALL(IF(名稱_所屬洲別="EU",ROW(名稱_所屬洲別),""),row(38:38))-1,0),"")} | F39: {=IFERROR(OFFSET('名稱對照'!E$1,SMALL(IF(名稱_所屬洲別="WA",ROW(名稱_所屬洲別),""),row(38:38))-1,0),"")} | G39: {=IFERROR(OFFSET('名稱對照'!E$1,SMALL(IF(名稱_所屬洲別="AP",ROW(名稱_所屬洲別),""),row(38:38))-1,0),"")}
B40: {=IFERROR(OFFSET('名稱對照'!E$1,SMALL(IF(名稱_所屬洲別="NA",ROW(名稱_所屬洲別),""),row(39:39))-1,0),"")} | C40: {=IFERROR(OFFSET('名稱對照'!E$1,SMALL(IF(名稱_所屬洲別="SA",ROW(名稱_所屬洲別),""),row(39:39))-1,0),"")} | D40: {=IFERROR(OFFSET('名稱對照'!E$1,SMALL(IF(名稱_所屬洲別="AF",ROW(名稱_所屬洲別),""),row(39:39))-1,0),"")} -> 塞內加爾 Senegal | E40: {=IFERROR(OFFSET('名稱對照'!E$1,SMALL(IF(名稱_所屬洲別="EU",ROW(名稱_所屬洲別),""),row(39:39))-1,0),"")} | F40: {=IFERROR(OFFSET('名稱對照'!E$1,SMALL(IF(名稱_所屬洲別="WA",ROW(名稱_所屬洲別),""),row(39:39))-1,0),"")} | G40: {=IFERROR(OFFSET('名稱對照'!E$1,SMALL(IF(名稱_所屬洲別="AP",ROW(名稱_所屬洲別),""),row(39:39))-1,0),"")}
...

Sheet 名稱對照
A1: 簡稱 | B1: 所屬洲別 | C1: 中文 | D1: 英文 | E1: 國別
A2: AFG | B2: WA | C2: 阿富汗 | D2: Afghanistan | E2: {=C2:C1002&CHAR(10)&D2:D1002} -> 阿富汗 Afghanistan
A3: AGO | B3: AF | C3: 安哥拉 | D3: Angola | E3: 安哥拉 Angola
A4: ALB | B4: EU | C4: 阿爾巴尼亞 | D4: Albania | E4: 阿爾巴尼亞 Albania
A5: ARE | B5: WA | C5: 阿拉伯聯合大公國 | D5: United Arab Emirates | E5: 阿拉伯聯合大公國 United Arab Emirates
A6: ARG | B6: SA | C6: 阿根廷 | D6: Argentina | E6: 阿根廷 Argentina
A7: ARM | B7: WA | C7: 亞美尼亞 | D7: Armenia | E7: 亞美尼亞 Armenia
A8: AUS | B8: AP | C8: 澳洲 | D8: Australia | E8: 澳洲 Australia
A9: CAN | B9: NA | C9: 加拿大 | D9: Canada | E9: 加拿大 Canada
A10: USA | B10: NA | C10: 美國 | D10: USA | E10: 美國 USA
A11: GRL | B11: NA | C11: 格陵蘭 | D11: Greenland | E11: 格陵蘭 Greenland
A12: AUT | B12: EU | C12: 奧地利 | D12: Austria | E12: 奧地利 Austria
A13: AZE | B13: WA | C13: 亞塞拜然共和國 | D13: Azerbaijan | E13: 亞塞拜然共和國 Azerbaijan
A14: BDI | B14: AF | C14: 蒲隆地 | D14: Burundi | E14: 蒲隆地 Burundi
... A178: PYF | B178: AP | C178: 玻里尼西亞 (大溪地) | D178: Polynesia (Tahitia) | E178: 玻里尼西亞 (大溪地) Polynesia (Tahitia)
